Workbook

Sheet Test Plan
A1: iSpace.az — Test Planı
A4: 1. ÜMUMİ MƏLUMAT
A5: Test obyekti | B5: iSpace.az — Apple Premium Partner e-commerce saytı (https://ispace.az). ASBIS platforması üzərində qurulub; AZ / EN / RU dillərində işləyir.
A6: Mühit | B6: Production (public). Ayrıca test mühiti yoxdur — bütün testlər canlı sistemə qarşı, etik qaydalara əməl edilməklə aparılır.
A7: Platforma / brauzer | B7: Desktop, Google Chrome (son stabil versiya). Ekran: 1920×1080.
A8: Məqsəd | B8: Saytın gəlir gətirən əsas axınını — Kataloq → Məhsul → Səbət — həm Web, həm API səviyyəsində yoxlamaq; manual və avtomat testləri əsaslandırılmış şəkildə ayırmaq; regression dəstini stabil avtomatlaşdırmaq.
A9: 2. SCOPE — TEST EDİLƏNLƏR
A10: Axtarış | B10: Məhsul axtarışı: ad, model, məhsul kodu, qismən söz, Azərbaycan hərfləri və.s
A11: Kateqoriya / listing | B11: Filtrlər (stok, qiymət aralığı, seriya, ekran, yaddaş, kamera, SIM, rəng, əlavə xüsusiyyətlər) və onların kombinasiyası, filtr sayğacları, sıralama (Məşhur / Aşağı qiymət / Yüksək qiymət), pagination.
A12: Məhsul səhifəsi (PDP) | B12: Qiymət və aylıq ödəniş göstərişi, variant seçimi (yaddaş / rəng), məhsul kodu, stok vəziyyəti, ön sifariş, əlavə proqram seçimi, miqdar, çatdırılma növü seçimi (submit-siz). 'Bütün proqramlara baxın' — taksit pəncərəsi: müddətlər, tərəfdaşlar, aylıq və ümumi məbləğ.
A13: Səbət | B13: Məhsul əlavə etmə (listing və PDP), miqdar dəyişmə, silmə, cəm hesablanması, qoruma proqramı sətri, endirim göstərişi, mini-səbət, səbətdən taksit pəncərəsi, səhifə yenilənəndə və sessiyada vəziyyətin qorunması.
A14: Lokalizasiya və xidmət səhifələri | B14: AZ / EN / RU keçidi scope-dakı səhifələrdə; tərcümə olunmamış və ya səhv mətnlər. Trade In və 'Çatdırılma və ödəniş' məlumat səhifələrinin açılması və şərtlərin səhifə daxilində ardıcıllığı (müraciət göndərilmir).
A15: 3. OUT OF SCOPE — VƏ SƏBƏBİ
A16: Checkout / sifariş / '1 kliklə al' | B16: Prodda real sifariş yaradır, operator müştəri ilə əlaqə saxlayır — geri qaytarıla bilməyən biznes əməliyyatı. Checkout-da yalnız göndərmədən yoxlanıla bilənlər test edildi: telefon və e-poçt validasiyası, çatdırılma haqqının xülasədə göstərilməsi, boş məcburi sahələr, mağazadan götürmə və rayon çatdırılma şərtləri. Sifariş heç vaxt göndərilmir; tapıntılar BUG-025, BUG-028, BUG-030.
A17: Ödəniş | B17: Real maliyyə əməliyyatı; test kartı imkanı yoxdur.
A18: Kredit və Trade-in müraciəti | B18: Real maliyyə/biznes müraciəti yaradır; bank və qiymətləndirmə prosesləri xarici sistemlərdir.
A19: Qeydiyyat / login | B19: Prodda hesab yaradılmır; login axını test edilmir.
A20: Əks əlaqə və abunə formu (submit) | B20: Real əməkdaşlara müraciət / spam yaradır. Yalnız client-side validasiya yoxlanıla bilər.
A21: Performance / load testing | B21: Prod sistemə yük vermək etik deyil və icazəsizdir.
A22: Security testing | B22: Injection, brute force kimi hücumlar prodda icazəsizdir. Yalnız passiv müşahidələr qeyd olunur.
A23: Cross-browser, mobil, responsive, əlçatanlıq | B23: Risk əsaslı olaraq desktop Chrome seçilib. Əlçatanlıq (klaviatura ilə naviqasiya, fokus, şəkillərin alt mətni) ayrıca alət və metodika (WCAG) tələb edir — növbəti mərhələyə saxlanılır.
A24: Mağaza xəritəsi, sosial şəbəkə linkləri | B24: Üçüncü tərəf servislərdir; yalnız linkin düzgün ünvana aparması yoxlanıla bilər.
A25: 4. RİSKLƏR VƏ AZALDILMASI
A26: R1 — Bot qoruması (Cloudflare) | B26: Avtomat sorğular bloklana bilər → testlər flaky olar. Azaldılma: 1-ci gün 30 ardıcıl sorğu + headless/headed Chrome sınağı; problem olarsa müəllimə dərhal məlumat.
A27: R2 — Dinamik katalog | B27: Qiymət, stok, məhsul adları gündəlik dəyişir. Azaldılma: test datası koda yazılmır, icra zamanı API-dən götürülür; assertion-lar konkret dəyərə yox, uyğunluq qaydalarına (oracle) əsaslanır.
A28: R3 — Tələb sənədinin olmaması | B28: Rəsmi spesifikasiya yoxdur. Azaldılma: tələblər müşahidəyə əsaslanan biznes qaydaları (BR-01…) kimi yazılıb və RTM-də izlənir; təsdiqlənməmiş fərziyyələr avtomat assertion-a çevrilmir.
A29: R4 — Prodda yan təsir | B29: Testlər real data yarada bilər. Azaldılma: yalnız geri qaytarıla bilən əməliyyatlar (axtarış, filtr, səbət); səbət test sonunda təmizlənir.
A30: R5 — Asinxron UI | B30: Loader ('Mağazanın yüklənməsi'), lazy-load, banner karuseli. Azaldılma: yalnız explicit wait, Thread.sleep qadağandır.
A31: R6 — Paylaşılan vəziyyət | B31: Başqa istifadəçilərin hərəkəti stoku dəyişə bilər. Azaldılma: qlobal say və sıraya ('ilk məhsul X-dir') assertion yazılmır.
A32: R7 — robots.txt məhdudiyyəti | B32: robots.txt /cart, /search, /checkout, /login və parametrli URL-ləri botlar üçün qadağan edir. Azaldılma: avtomat testlərin həcmi minimal, hər test tək brauzer sessiyası ilə; real sifariş/müraciət göndərilmir.
A33: 5. TEST SƏVİYYƏLƏRİ VƏ NÖVLƏRİ
A34: Səviyyələr | B34: API (backend məntiqi, validasiya, kontrakt) → UI / E2E (istifadəçi axınları). Test piramidası: kombinasiya və validasiyaların çoxu API-də, UI-da yalnız kritik axınlar və UI-a məxsus davranış.
A35: Növlər | B35: Functional (pozitiv / neqativ), Smoke, Regression, Localization, Exploratory (session-based), UI–API uyğunluğu.
A36: Test dizayn texnikaları | B36: Equivalence Partitioning, Boundary Value Analysis, Decision Table (filtr kombinasiyaları), State Transition (səbət vəziyyətləri), Error Guessing, Consistency Oracle (listing = PDP = səbət).
A37: 6. PRİORİTET VƏ SEVERİTY ŞKALASI
A38: Test case prioriteti | B38: Risk = biznes təsiri × baş vermə ehtimalı. Critical: gəlir axınını bloklayır (səbətə əlavə, qiymət). High: əsas funksiya səhv işləyir (filtr, sıralama, axtarış). Medium: köməkçi funksiya. Low: kosmetik.
A39: Bug severity | B39: Critical (Blocker) / High (Major) / Medium (Moderate) / Low — kurs materialındakı şkala.
A40: Bug priority | B40: P1 — dərhal · P2 — yüksək · P3 — orta · P4 — aşağı.
A41: 7. AVTOMATLAŞDIRMA YANAŞMASI
A42: Seçim meyarları | B42: 'Decision Matrix' sheet-inə əsasən: təkrarlanma tezliyi, risk, determinizm, kənar asılılıq, yoxlamanın təbiəti (kodlar A1–A3, M1–M5).
...

Sheet Test Scenarios
A1: Test Ssenariləri — iSpace.az
A4: Ssenari ID | B4: Modul | C4: Test ssenarisi | D4: Prioritet | E4: Əlaqəli tələb | F4: Test case sayı | G4: Avtomat | H4: Regression
A5: SC-001 | B5: Kateqoriya (PLP) | C5: İstifadəçi iPhone kateqoriyasını açdıqda məhsul kartları ad, qiymət, aylıq ödəniş və stok vəziyyətinə uyğun düymə ilə göstərilməli, kartdakı qiymət məhsul səhifəsindəki ilə eyni olmalıdır. | D5: P1 — Critical | E5: UJ-01 · BR-01, BR-11 | F5: =COUNTIF('Web Test Cases'!$B$5:$B$130,A5) -> 4 | G5: =COUNTIFS('Web Test Cases'!$B$5:$B$130,A5,'Web Test Cases'!$M$5:$M$130,"Avtomat") -> 4 | H5: =COUNTIFS('Web Test Cases'!$B$5:$B$130,A5,'Web Test Cases'!$O$5:$O$130,"Bəli") -> 4
A6: SC-002 | B6: Kateqoriya (PLP) | C6: İstifadəçi stok, yaddaş və rəng filtrlərini tək-tək və birlikdə tətbiq etdikdə yalnız seçimə uyğun məhsullar göstərilməli, filtr sayğacları nəticə sayına bərabər olmalıdır. | D6: P2 — High | E6: UJ-03 · BR-02, BR-12 | F6: =COUNTIF('Web Test Cases'!$B$5:$B$130,A6) -> 9 | G6: =COUNTIFS('Web Test Cases'!$B$5:$B$130,A6,'Web Test Cases'!$M$5:$M$130,"Avtomat") -> 7 | H6: =COUNTIFS('Web Test Cases'!$B$5:$B$130,A6,'Web Test Cases'!$O$5:$O$130,"Bəli") -> 3
A7: SC-003 | B7: Kateqoriya (PLP) | C7: İstifadəçi qiymət aralığı daxil etdikdə yalnız bu aralıqdakı (sərhədlər daxil) məhsullar göstərilməli, keçərsiz dəyər daxil etdikdə sistem onu rədd etməlidir. | D7: P2 — High | E7: UJ-03 · BR-04 | F7: =COUNTIF('Web Test Cases'!$B$5:$B$130,A7) -> 5 | G7: =COUNTIFS('Web Test Cases'!$B$5:$B$130,A7,'Web Test Cases'!$M$5:$M$130,"Avtomat") -> 3 | H7: =COUNTIFS('Web Test Cases'!$B$5:$B$130,A7,'Web Test Cases'!$O$5:$O$130,"Bəli") -> 2
A8: SC-004 | B8: Kateqoriya (PLP) | C8: İstifadəçi qiymətə görə sıralama seçdikdə və səhifələr arasında keçdikdə məhsullar bütün səhifələr boyu artan və ya azalan sırada, hər biri yalnız bir dəfə göstərilməlidir. | D8: P2 — High | E8: UJ-03 · BR-03, BR-05, BR-14 | F8: =COUNTIF('Web Test Cases'!$B$5:$B$130,A8) -> 5 | G8: =COUNTIFS('Web Test Cases'!$B$5:$B$130,A8,'Web Test Cases'!$M$5:$M$130,"Avtomat") -> 4 | H8: =COUNTIFS('Web Test Cases'!$B$5:$B$130,A8,'Web Test Cases'!$O$5:$O$130,"Bəli") -> 2
A9: SC-005 | B9: Kateqoriya (PLP) | C9: İstifadəçi alt-kateqoriya çipini və ya Seriya filtrini seçdikdə yalnız həmin seriyanın məhsulları göstərilməli, sayğaclar ümumi məhsul sayı ilə uyğun olmalıdır. | D9: P2 — High | E9: UJ-03 · BR-12, BR-18 | F9: =COUNTIF('Web Test Cases'!$B$5:$B$130,A9) -> 3 | G9: =COUNTIFS('Web Test Cases'!$B$5:$B$130,A9,'Web Test Cases'!$M$5:$M$130,"Avtomat") -> 3 | H9: =COUNTIFS('Web Test Cases'!$B$5:$B$130,A9,'Web Test Cases'!$O$5:$O$130,"Bəli") -> 1
A10: SC-006 | B10: Kateqoriya (PLP) | C10: İstifadəçi texniki xüsusiyyət filtrlərini (ekran, kamera, video, SIM, məhsul tipi) seçdikdə nəticələr məhsulun PDP-dəki texniki göstəriciləri ilə uyğun olmalıdır. | D10: P3 — Medium | E10: UJ-03 · BR-18 | F10: =COUNTIF('Web Test Cases'!$B$5:$B$130,A10) -> 5 | G10: =COUNTIFS('Web Test Cases'!$B$5:$B$130,A10,'Web Test Cases'!$M$5:$M$130,"Avtomat") -> 3 | H10: =COUNTIFS('Web Test Cases'!$B$5:$B$130,A10,'Web Test Cases'!$O$5:$O$130,"Bəli") -> 0
A11: SC-007 | B11: Kateqoriya (PLP) | C11: İstifadəçi Rəng və 'Əlavə xüsusiyyətlər' filtrlərini seçdikdə uyğun məhsulların hamısı tapılmalı, filtr dəyərləri azərbaycanca göstərilməlidir. | D11: P2 — High | E11: UJ-03 · BR-18 | F11: =COUNTIF('Web Test Cases'!$B$5:$B$130,A11) -> 4 | G11: =COUNTIFS('Web Test Cases'!$B$5:$B$130,A11,'Web Test Cases'!$M$5:$M$130,"Avtomat") -> 1 | H11: =COUNTIFS('Web Test Cases'!$B$5:$B$130,A11,'Web Test Cases'!$O$5:$O$130,"Bəli") -> 0
A12: SC-008 | B12: Kateqoriya (PLP) | C12: İstifadəçi filtr seçib 'Tətbiq et' basdıqda nəticə və digər qrupların sayğacları yenilənməli, aktiv filtrlər görünməli və tək-tək silinə bilməlidir. | D12: P2 — High | E12: UJ-03 · BR-02, BR-12 | F12: =COUNTIF('Web Test Cases'!$B$5:$B$130,A12) -> 4 | G12: =COUNTIFS('Web Test Cases'!$B$5:$B$130,A12,'Web Test Cases'!$M$5:$M$130,"Avtomat") -> 2 | H12: =COUNTIFS('Web Test Cases'!$B$5:$B$130,A12,'Web Test Cases'!$O$5:$O$130,"Bəli") -> 0
A13: SC-009 | B13: Kateqoriya (PLP) | C13: İstifadəçi filtrləri sıralama, səhifələmə, dil dəyişmə və brauzerin 'Geri' düyməsi ilə birlikdə istifadə etdikdə filtr vəziyyəti qorunmalı və nəticə dəqiq olmalıdır. | D13: P2 — High | E13: UJ-03 · BR-18 | F13: =COUNTIF('Web Test Cases'!$B$5:$B$130,A13) -> 7 | G13: =COUNTIFS('Web Test Cases'!$B$5:$B$130,A13,'Web Test Cases'!$M$5:$M$130,"Avtomat") -> 4 | H13: =COUNTIFS('Web Test Cases'!$B$5:$B$130,A13,'Web Test Cases'!$O$5:$O$130,"Bəli") -> 2
A14: SC-010 | B14: Məhsul səhifəsi (PDP) | C14: İstifadəçi məhsul səhifəsini açdıqda ad, məhsul kodu, qiymət, aylıq ödəniş, şəkillər və texniki göstəricilər listing ilə uyğun göstərilməlidir. | D14: P1 — Critical | E14: UJ-01 · BR-01, BR-08 | F14: =COUNTIF('Web Test Cases'!$B$5:$B$130,A14) -> 3 | G14: =COUNTIFS('Web Test Cases'!$B$5:$B$130,A14,'Web Test Cases'!$M$5:$M$130,"Avtomat") -> 2 | H14: =COUNTIFS('Web Test Cases'!$B$5:$B$130,A14,'Web Test Cases'!$O$5:$O$130,"Bəli") -> 2
A15: SC-011 | B15: Məhsul səhifəsi (PDP) | C15: İstifadəçi məhsul səhifəsində variant, miqdar, qoruma proqramı və çatdırılma seçdikdə məhsul məlumatı və məbləğ seçimə uyğun yenilənməlidir. | D15: P2 — High | E15: UJ-01 · BR-06, BR-15 | F15: =COUNTIF('Web Test Cases'!$B$5:$B$130,A15) -> 7 | G15: =COUNTIFS('Web Test Cases'!$B$5:$B$130,A15,'Web Test Cases'!$M$5:$M$130,"Avtomat") -> 5 | H15: =COUNTIFS('Web Test Cases'!$B$5:$B$130,A15,'Web Test Cases'!$O$5:$O$130,"Bəli") -> 3
A16: SC-012 | B16: Məhsul səhifəsi (PDP) | C16: İstifadəçi stokda olmayan və ya mövcud olmayan məhsulu açdıqda məhsul alına bilməməli və aydın vəziyyət mesajı göstərilməlidir. | D16: P2 — High | E16: UJ-01 · BR-11 | F16: =COUNTIF('Web Test Cases'!$B$5:$B$130,A16) -> 2 | G16: =COUNTIFS('Web Test Cases'!$B$5:$B$130,A16,'Web Test Cases'!$M$5:$M$130,"Avtomat") -> 1 | H16: =COUNTIFS('Web Test Cases'!$B$5:$B$130,A16,'Web Test Cases'!$O$5:$O$130,"Bəli") -> 1
... A28: SC-024 | B28: Xidmət səhifələri | C28: İstifadəçi Trade In və 'Çatdırılma və ödəniş' məlumat səhifələrini açdıqda səhifə açılmalı, şərtlər tam və seçilmiş dildə göstərilməli, eyni şərt (müddət, qiymət) səhifənin bütün hissələrində (mətn, cədvəl, FAQ) eyni yazılmalıdır. | D28: P3 — Medium | E28: UJ-01, UJ-05 · BR-10, BR-13 | F28: =COUNTIF('Web Test Cases'!$B$5:$B$130,A28) -> 3 | G28: =COUNTIFS('Web Test Cases'!$B$5:$B$130,A28,'Web Test Cases'!$M$5:$M$130,"Avtomat") -> 0 | H28: =COUNTIFS('Web Test Cases'!$B$5:$B$130,A28,'Web Test Cases'!$O$5:$O$130,"Bəli") -> 0
C29: Cəmi | F29: =SUM(F5:F28) -> 126 | G29: =SUM(G5:G28) -> 74 | H29: =SUM(H5:H28) -> 40

Sheet Web Test Cases
A1: Test Case-lər — iSpace.az (Web)
A4: Test Case ID | B4: Ssenari ID | C4: Modul | D4: Başlıq (Title) | E4: Prioritet | F4: Test növü | G4: Ön şərtlər | H4: Test addımları | I4: Test datası | J4: Gözlənilən nəticə | K4: Faktiki nəticə | L4: Status | M4: Avtomat / Manual | N4: Səbəb (Decision Matrix) | O4: Regression | P4: Smoke | Q4: Bug ID | R4: Əlaqəli tələb (BR) | S4: Avtomatlaşdırma statusu (Gauge) | T4: Avtomatlaşdırma qeydi
A5: TC_PLP_POS_001 | B5: SC-001 | C5: Kateqoriya (PLP) | D5: iPhone kateqoriyası açıldıqda başlıq, breadcrumb, məhsul sayı və məhsul kartları göstərilir | E5: P1 — Critical | F5: Pozitiv · Funksional | G5: Ümumi ön şərt (P0): Chrome son versiya, inkognito pəncərə, 1920×1080, AZ dili, login olmadan | H5: 1. Brauzerdə https://ispace.az/category/iphone ünvanını aç 2. 'Mağazanın yüklənməsi' yazısı yox olana qədər gözlə 3. Səhifə başlığını oxu 4. Başlığın üstündəki breadcrumb-u oxu 5. Səhifənin yuxarısındakı 'N Məhsul' mətnindən nəticə sayını qeyd et 6. Səhifədə məhsul kartlarının göstərildiyinə bax | I5: URL: /category/iphone | J5: 1. Səhifə başlığı 'iPhone'. 2. Breadcrumb: 'Ana səhifə > iPhone'. 3. 'N Məhsul' mətni göstərilir, N > 0. 4. Ən azı 1 məhsul kartı var. | K5: Səhifə yükləndi; başlıq, breadcrumb, məhsul sayı və kartlar göstərildi. Bütün yoxlama nöqtələri gözlənilən nəticəyə uyğundur. | L5: Pass | M5: Avtomat | N5: A1 — əsas axının giriş nöqtəsi, hər release-də | O5: Bəli | P5: Bəli | R5: BR-01, BR-11 | S5: Avtomatlaşdırılıb — PASS, 16.10.2026 | T5: —
A6: TC_PLP_POS_002 | B6: SC-001 | C6: Kateqoriya (PLP) | D6: Hər məhsul kartında ad, qiymət, aylıq ödəniş və düymə göstərilir | E6: P1 — Critical | F6: Pozitiv · Funksional | G6: Ümumi ön şərt (P0): Chrome son versiya, inkognito pəncərə, 1920×1080, AZ dili, login olmadan | H6: 1. https://ispace.az/category/iphone ünvanını aç 2. 1-ci səhifədəki hər məhsul kartında şəkli, adı və qiyməti yoxla 3. Stokda olan kartlarda aylıq ödəniş mətnini ('Ayda X ₼-dan') yoxla 4. Hər kartın altındakı düymənin mətnini qeyd et | I6: 1-ci səhifənin bütün kartları | J6: Hər kartda: şəkil; boş olmayan ad; 'X XXX ₼' formatında qiymət (X > 0); stokda olan məhsullarda aylıq ödəniş mətni; vəziyyətə uyğun düymə: 'Səbətə', 'Ön sifariş', 'Tezliklə satışda' və ya 'Mənə xəbər ver' (BR-11). | K6: Bütün kartlarda şəkil, ad, '₼' formatında qiymət və düymə var; boş sahə yoxdur. Kartlarda 4 fərqli düymə vəziyyəti müşahidə olundu: 'Səbətə', 'Ön sifariş', 'Tezliklə satışda', 'Mənə xəbər ver' (BR-11 yeniləndi). | L6: Pass | M6: Avtomat | N6: A2 — struktur yoxlaması, kart sayı çox (A3) | O6: Bəli | P6: Xeyr | R6: BR-01, BR-11 | S6: Avtomatlaşdırılıb — PASS, 16.10.2026 | T6: Kart sayı = şəkil = ad = qiymət = düymə sayı (düymə növündən asılı olmayaraq); bütün qiymətlərdə '₼', boş ad yoxdur
A7: TC_PLP_POS_003 | B7: SC-001 | C7: Kateqoriya (PLP) | D7: Kartdakı qiymət məhsul səhifəsindəki qiymətlə eynidir | E7: P1 — Critical | F7: Pozitiv · Funksional | G7: Ümumi ön şərt (P0): Chrome son versiya, inkognito pəncərə, 1920×1080, AZ dili, login olmadan | H7: 1. https://ispace.az/category/iphone ünvanını aç 2. 'Səbətə' düyməsi olan ilk kartın adını və qiymətini qeyd et 3. Həmin kartın şəklinə klik et — məhsul səhifəsi açılır 4. Məhsul səhifəsindəki adı və qiyməti qeyd etdiyin dəyərlərlə müqayisə et | I7: Stokda olan istənilən məhsul (icra zamanı seçilir) | J7: PDP-dəki ad və qiymət kartdakı ilə hərfbəhərf eynidir. | K7: Kartdakı ad və qiymət PDP-dəki ilə hərfbəhərf eynidir. | L7: Pass | M7: Avtomat | N7: A1, A2 — qiymət səhvi birbaşa pul itkisidir; dəyişkən qiymətdə belə sınmır | O7: Bəli | P7: Xeyr | R7: BR-01 | S7: Avtomatlaşdırılıb — PASS, 16.10.2026 | T7: İlk kart icra zamanı seçilir, ad və qiymət dəyişənə saxlanır
A8: TC_PLP_POS_004 | B8: SC-001 | C8: Kateqoriya (PLP) | D8: Stokda olan məhsulun kartında 'Səbətə', olmayanda 'Ön sifariş' / 'Mənə xəbər ver' düyməsi göstərilir | E8: P2 — High | F8: Pozitiv · Funksional | G8: Ümumi ön şərt (P0): Chrome son versiya, inkognito pəncərə, 1920×1080, AZ dili, login olmadan | H8: 1. https://ispace.az/category/iphone ünvanını aç 2. Filtr panelinin 'Stokda var' qrupunda 'Mövcuddur' seç 3. Filtr panelinin altındakı 'Tətbiq et' düyməsini bas 4. 1-ci səhifədəki bütün kartların düyməsini qeyd et 5. 'Mövcuddur' seçimini götür, 'Mövcud deyil' seç 6. Filtr panelinin altındakı 'Tətbiq et' düyməsini bas 7. 1-ci səhifədəki bütün kartların düyməsini qeyd et | I8: Stok filtri: Mövcuddur / Mövcud deyil | J8: Stokda olan bütün kartlarda 'Səbətə'; stokda olmayan kartlarda 'Mənə xəbər ver' və ya 'Ön sifariş'. Stokda olmayan kartda 'Səbətə' düyməsi yoxdur. | K8: Stokda olan kartlarda 'Səbətə', stokda olmayanlarda 'Mənə xəbər ver' və ya 'Ön sifariş' göstərilir; stokda olmayan kartda 'Səbətə' yoxdur. | L8: Pass | M8: Avtomat | N8: A2 — stokda olmayan məhsulun satışı biznes riskidir | O8: Bəli | P8: Xeyr | R8: BR-11 | S8: Avtomatlaşdırılıb — PASS, 16.10.2026 | T8: 'Mövcuddur' filtrində ad sayı = 'Səbətə' sayı; 'Mövcud deyil' filtrində 'Səbətə' sayı = 0
A9: TC_PLP_POS_005 | B9: SC-002 | C9: Kateqoriya (PLP) | D9: 'Mövcuddur' filtri: nəticə sayı sayğaca bərabərdir | E9: P2 — High | F9: Pozitiv · Funksional | G9: Ümumi ön şərt (P0): Chrome son versiya, inkognito pəncərə, 1920×1080, AZ dili, login olmadan | H9: 1. https://ispace.az/category/iphone ünvanını aç 2. Filtr panelinin 'Stokda var' qrupunda 'Mövcuddur (N)' sayğacındakı N-i qeyd et 3. 'Mövcuddur' seç 4. Filtr panelinin altındakı 'Tətbiq et' düyməsini bas 5. Səhifənin yuxarısındakı 'N Məhsul' mətnindən nəticə sayını qeyd et 6. Kartların hamısında 'Səbətə' düyməsi olduğunu yoxla | I9: N — icra zamanı oxunur (04.10-da 41) | J9: 1. 'N Məhsul' mətni sayğacdakı N ilə eynidir. 2. Bütün kartlar stokdadır ('Səbətə' düyməsi). | K9: 'Mövcuddur' filtrindən sonra nəticə sayı sayğacdakı rəqəmə bərabərdir; bütün kartlar stokdadır. | L9: Pass | M9: Avtomat | N9: A2 — say qaydaya əsaslanır, konkret rəqəm koda yazılmır | O9: Bəli | P9: Xeyr | R9: BR-02 | S9: Avtomatlaşdırılıb — PASS, 16.10.2026 | T9: Sayğac ('Movcuddur (N)') icra zamanı oxunur; Java: 'N Məhsul' = N
A10: TC_PLP_POS_006 | B10: SC-002 | C10: Kateqoriya (PLP) | D10: Bir filtr qrupunda sayğacların cəmi ümumi məhsul sayına bərabərdir | E10: P3 — Medium | F10: Pozitiv · Funksional | G10: Ümumi ön şərt (P0): Chrome son versiya, inkognito pəncərə, 1920×1080, AZ dili, login olmadan | H10: 1. https://ispace.az/category/iphone ünvanını aç 2. Səhifənin yuxarısındakı 'N Məhsul' mətnindən nəticə sayını qeyd et — ümumi N 3. Filtr panelinin 'Stokda var' qrupundakı bütün sayğacları topla 4. 'Yaddaş' qrupundakı bütün sayğacları topla ('+ Daha çox göstər' varsa bas) 5. 'SIM kart növü' qrupundakı bütün sayğacları topla 6. Hər qrupun cəmini ümumi N ilə müqayisə et | I10: 04.10 müşahidəsi: 41+172 = 213; 66+66+36+32+13 = 213; 187+26 = 213 | J10: Hər bir-birini istisna edən qrupda sayğacların cəmi = N. | K10: Stok, yaddaş və SIM qruplarında sayğacların cəmi ümumi məhsul sayına bərabərdir (BR-12 təsdiqləndi). | L10: Pass | M10: Avtomat | N10: A2, A3 — ucuz, sayma bug-larını tutur | O10: Xeyr | P10: Xeyr | R10: BR-12 | S10: Avtomatlaşdırılıb — PASS, 16.10.2026 | T10: Stok və SIM qruplarında sayğacların cəmi = 'N Məhsul'
A11: TC_PLP_POS_007 | B11: SC-002 | C11: Kateqoriya (PLP) | D11: Yaddaş filtri yalnız seçilmiş yaddaşlı məhsulları göstərir | E11: P2 — High | F11: Pozitiv · Funksional | G11: Ümumi ön şərt (P0): Chrome son versiya, inkognito pəncərə, 1920×1080, AZ dili, login olmadan | H11: 1. https://ispace.az/category/iphone ünvanını aç 2. Filtr panelinin 'Yaddaş' qrupunda '256 GB (N)' sayğacındakı N-i qeyd et 3. '256 GB' seç 4. Filtr panelinin altındakı 'Tətbiq et' düyməsini bas 5. Səhifənin yuxarısındakı 'N Məhsul' mətnindən nəticə sayını qeyd et 6. 1-ci səhifədəki bütün kartların adında '256 GB' olduğunu yoxla | I11: Yaddaş = 256 GB | J11: 1. Bütün kartların adında '256 GB' var. 2. Nəticə sayı = N. | K11: '256 GB' filtri: bütün kartların adında '256 GB' var; nəticə sayı 66 = sayğac (66). | L11: Pass | M11: Avtomat | N11: A1, A2 | O11: Bəli | P11: Xeyr | R11: BR-02 | S11: Avtomatlaşdırılıb — PASS, 16.10.2026 | T11: PLP_POS_009-un sadə variantı: yalnız 256 GB filtri; bütün adlarda '256 GB'
A12: TC_PLP_POS_008 | B12: SC-002 | C12: Kateqoriya (PLP) | D12: Rəng filtri yalnız seçilmiş rəngli məhsulları göstərir | E12: P3 — Medium | F12: Pozitiv · Funksional | G12: Ümumi ön şərt (P0): Chrome son versiya, inkognito pəncərə, 1920×1080, AZ dili, login olmadan | H12: 1. https://ispace.az/category/iphone ünvanını aç 2. Filtr panelinin 'Rəng' qrupunda 'Qara (N)' sayğacındakı N-i qeyd et 3. 'Qara' seç 4. Filtr panelinin altındakı 'Tətbiq et' düyməsini bas 5. Səhifənin yuxarısındakı 'N Məhsul' mətnindən nəticə sayını qeyd et 6. 1-ci səhifədəki kartların adında və şəklində rəngi yoxla | I12: Rəng = Qara | J12: Bütün nəticələr qara rəngli modellərdir (Black, Black Titanium, Space Black və s. daxil). Say = sayğac. | K12: 'Qara' filtrinin nəticələri qara rəngli modellərdir; say sayğaca bərabərdir. | L12: Pass | M12: Manual | N12: M1 — kart adlarında rəng adları qarışıqdır (Qara / Black / Black Titanium), avtomat oracle etibarsızdır | O12: Xeyr | P12: Xeyr | R12: BR-02
A13: TC_PLP_POS_009 | B13: SC-002 | C13: Kateqoriya (PLP) | D13: '256 GB' və 'Mövcuddur' birlikdə seçildikdə yalnız hər iki şərtə uyğun məhsullar göstərilir (VƏ məntiqi) | E13: P2 — High | F13: Pozitiv · Funksional | G13: Ümumi ön şərt (P0): Chrome son versiya, inkognito pəncərə, 1920×1080, AZ dili, login olmadan | H13: 1. https://ispace.az/category/iphone ünvanını aç 2. 'Yaddaş' qrupunda '256 GB' seç 3. 'Stokda var' qrupunda 'Mövcuddur' seç 4. Filtr panelinin altındakı 'Tətbiq et' düyməsini bas 5. Səhifənin yuxarısındakı 'N Məhsul' mətnindən nəticə sayını qeyd et 6. Hər kartın adında '256 GB' və altında 'Səbətə' düyməsi olduğunu yoxla | I13: Yaddaş = 256 GB + Stok = Mövcuddur | J13: Bütün nəticələr həm 256 GB-dır, həm də stokdadır ('Səbətə'). Nəticə sayı hər iki tək filtrin sayından ≤-dir. | K13: 256 GB + Mövcuddur: nəticələr hər iki şərtə uyğundur ('VƏ' məntiqi). | L13: Pass | M13: Avtomat | N13: A2, A3 — kombinasiya məntiqi | O13: Bəli | P13: Xeyr | R13: BR-02, BR-12 | S13: Avtomatlaşdırılıb — PASS, 16.10.2026 | T13: Desktop (1920×1080) görünüşdə filtr seçiləndə dərhal tətbiq olunur — 'Tətbiq et' yalnız mobil görünüşdədir; hər kartda 'Səbətə' olduğu say ilə yoxlanır
A14: TC_PLP_POS_010 | B14: SC-002 | C14: Kateqoriya (PLP) | D14: '256 GB' və '512 GB' birlikdə seçildikdə nəticə sayı iki sayğacın cəminə bərabərdir (VƏ YA məntiqi) | E14: P3 — Medium | F14: Pozitiv · Funksional | G14: Ümumi ön şərt (P0): Chrome son versiya, inkognito pəncərə, 1920×1080, AZ dili, login olmadan | H14: 1. https://ispace.az/category/iphone ünvanını aç 2. 'Yaddaş' qrupunda '256 GB (N1)' və '512 GB (N2)' sayğaclarını qeyd et 3. '256 GB' seç 4. '512 GB' seç 5. Filtr panelinin altındakı 'Tətbiq et' düyməsini bas 6. Səhifənin yuxarısındakı 'N Məhsul' mətnindən nəticə sayını qeyd et 7. Nəticə sayını N1 + N2 ilə müqayisə et | I14: Yaddaş = 256 GB + 512 GB | J14: Bütün nəticələr 256 GB və ya 512 GB-dır. Nəticə sayı = N1 + N2. | K14: 256 GB + 512 GB: nəticələr hər iki dəyərdən birinə uyğundur, say = N1 + N2 ('VƏ YA' məntiqi). | L14: Pass | M14: Avtomat | N14: A2, A3 | O14: Xeyr | P14: Xeyr | R14: BR-12 | S14: Avtomatlaşdırılıb — PASS, 16.10.2026 | T14: 256 GB + 512 GB: 'N Məhsul' = iki sayğacın cəmi
A15: TC_PLP_POS_011 | B15: SC-002 | C15: Kateqoriya (PLP) | D15: Filtrlər təmizlənəndə ilkin siyahı bərpa olunur | E15: P3 — Medium | F15: Pozitiv · Funksional | G15: Ümumi ön şərt (P0): Chrome son versiya, inkognito pəncərə, 1920×1080, AZ dili, login olmadan | H15: 1. https://ispace.az/category/iphone ünvanını aç 2. Səhifənin yuxarısındakı 'N Məhsul' mətnindən nəticə sayını qeyd et — ümumi N 3. 'Yaddaş' qrupunda '256 GB' seç 4. 'Stokda var' qrupunda 'Mövcuddur' seç 5. Filtr panelinin altındakı 'Tətbiq et' düyməsini bas 6. Seçilmiş hər iki filtrin işarəsini götür 7. Filtr panelinin altındakı 'Tətbiq et' düyməsini bas 8. Səhifənin yuxarısındakı 'N Məhsul' mətnindən nəticə sayını qeyd et 9. Nəticə sayını N ilə müqayisə et | I15: — | J15: Məhsul sayı yenidən N-dir, filtr seçimləri boşdur. | K15: Filtrlər təmizləndikdən sonra ilkin məhsul sayı bərpa olundu. | L15: Pass | M15: Avtomat | N15: A2 | O15: Xeyr | P15: Xeyr | R15: BR-02, BR-12 | S15: Avtomatlaşdırılıb — PASS, 16.10.2026 | T15: 256 GB + 'Mövcuddur' seçilib ləğv olunur; ilkin məhsul sayı bərpa olunur
A16: TC_PLP_POS_012 | B16: SC-002 | C16: Kateqoriya (PLP) | D16: Filtrli səhifə yeniləndikdə və link yeni tabda açıldıqda filtr qorunur | E16: P3 — Medium | F16: Pozitiv · Funksional | G16: Ümumi ön şərt (P0): Chrome son versiya, inkognito pəncərə, 1920×1080, AZ dili, login olmadan | H16: 1. https://ispace.az/category/iphone ünvanını aç 2. 'Yaddaş' qrupunda '256 GB' seç 3. Filtr panelinin altındakı 'Tətbiq et' düyməsini bas 4. Səhifənin yuxarısındakı 'N Məhsul' mətnindən nəticə sayını qeyd et 5. Klaviaturada F5 bas (səhifəni yenilə) 6. Filtrin seçili qaldığını və nəticə sayını yoxla 7. Ünvan sətrindəki URL-i kopyala 8. Yeni tab aç və URL-i yapışdırıb aç 9. Filtrin seçili qaldığını və nəticə sayını yoxla | I16: — | J16: Hər iki halda filtr seçili qalır, nəticə sayı və kartlar eynidir. | K16: Filtr səhifə yeniləndikdə və link yeni tabda açıldıqda qorunur. | L16: Pass | M16: Avtomat | N16: A2 | O16: Xeyr | P16: Xeyr | R16: BR-02, BR-12 | S16: Avtomatlaşdırılıb — PASS, 16.10.2026 | T16: F5-dən sonra və eyni link yeni tabda açıldıqda say və '256 GB' filtri qorunur
A17: TC_PLP_NEG_013 | B17: SC-002 | C17: Kateqoriya (PLP) | D17: Nəticəsiz filtr kombinasiyasında boş vəziyyət mesajı göstərilir | E17: P3 — Medium | F17: Neqativ · Funksional | G17: Ümumi ön şərt (P0): Chrome son versiya, inkognito pəncərə, 1920×1080, AZ dili, login olmadan | H17: 1. https://ispace.az/category/iphone ünvanını aç 2. Filtr panelinin 'Qiymət ₼' qrupunda 'qədər' sahəsinə test datasındakı dəyəri yaz 3. Filtr panelinin altındakı 'Tətbiq et' düyməsini bas 4. Səhifədə göstərilən mesaja bax | I17: 'qədər' = 100 (bütün qiymətlərdən aşağı) | J17: 'Məhsul tapılmadı' tipli mesaj və filtrləri təmizləmək imkanı göstərilir. Səhifə xəta vermir. | K17: Nəticəsiz kombinasiyada 'Məhsul tapılmadı. Daha az filtrdən istifadə edin və ya Hamısını silin' mesajı göstərildi. | L17: Pass | M17: Manual | N17: M3 — kataloq dəyişdikcə 'nəticəsiz' kombinasiya nəticə verə bilər | O17: Xeyr | P17: Xeyr | R17: BR-02, BR-12
A18: TC_PLP_POS_014 | B18: SC-003 | C18: Kateqoriya (PLP) | D18: Qiymət aralığı daxilində olan məhsullar göstərilir | E18: P2 — High | F18: Pozitiv · Funksional | G18: Ümumi ön şərt (P0): Chrome son versiya, inkognito pəncərə, 1920×1080, AZ dili, login olmadan | H18: 1. https://ispace.az/category/iphone ünvanını aç 2. 'Qiymət ₼' qrupunda 'dən' sahəsinə 2000 yaz 3. 'qədər' sahəsinə 3000 yaz 4. Filtr panelinin altındakı 'Tətbiq et' düyməsini bas 5. Bütün səhifələrdəki kartların qiymətini yoxla | I18: min = 2000, max = 3000 (etibarlı sinif) | J18: Bütün kartların qiyməti 2000 ≤ qiymət ≤ 3000. Nəticə sayı > 0. | K18: 2000–3000 ₼ aralığında bütün nəticələrin qiyməti aralıq daxilindədir; nəticə sayı > 0. | L18: Pass | M18: Avtomat | N18: A1, A2 | O18: Bəli | P18: Xeyr | R18: BR-04 | S18: Avtomatlaşdırılıb — PASS, 16.10.2026 | T18: Desktop-da qiymət filtri Enter ilə tətbiq olunur; Java: bütün qiymətlər 2000–3000 aralığındadır
A19: TC_PLP_BVA_015 | B19: SC-003 | C19: Kateqoriya (PLP) | D19: Qiymət filtrinin sərhədləri daxildir (min = max = məhsulun qiyməti) | E19: P2 — High | F19: BVA · Funksional | G19: Ümumi ön şərt (P0): Chrome son versiya, inkognito pəncərə, 1920×1080, AZ dili, login olmadan | H19: 1. https://ispace.az/category/iphone ünvanını aç 2. 'Səbətə' düyməsi olan bir məhsulun qiymətini (Q) qeyd et 3. 'dən' sahəsinə Q yaz 4. 'qədər' sahəsinə Q yaz 5. Filtr panelinin altındakı 'Tətbiq et' düyməsini bas 6. Həmin məhsulun nəticədə olduğunu və bütün qiymətlərin Q olduğunu yoxla | I19: Q — icra zamanı seçilən məhsulun qiyməti (məs. 2409) | J19: Həmin məhsul nəticədədir; bütün nəticələrin qiyməti = Q. | K19: min = max = 2409 ₼: yalnız qiyməti 2409 ₼ olan məhsullar göstərildi — sərhəd dəyəri daxildir (BR-04 təsdiqləndi). | L19: Pass | M19: Avtomat | N19: A2 — sərhəd səhvi (< əvəzinə ≤) tipik regression-dur | O19: Bəli | P19: Xeyr | R19: BR-04 | S19: Avtomatlaşdırılıb — PASS, 16.10.2026 | T19: Qiymət filtri desktop-da Enter ilə tətbiq olunur; Q icra zamanı ilk kartdan götürülür
A20: TC_PLP_BVA_016 | B20: SC-003 | C20: Kateqoriya (PLP) | D20: Sərhəddən bir vahid kənar dəyər məhsulu xaric edir | E20: P3 — Medium | F20: BVA · Funksional | G20: Ümumi ön şərt (P0): Chrome son versiya, inkognito pəncərə, 1920×1080, AZ dili, login olmadan | H20: 1. https://ispace.az/category/iphone ünvanını aç 2. Bir məhsulun qiymətini (Q) qeyd et 3. 'dən' = Q + 1, 'qədər' = Q + 1000 yaz 4. Filtr panelinin altındakı 'Tətbiq et' düyməsini bas 5. Q qiymətli məhsulun nəticədə olmadığını yoxla 6. 'dən' = Q − 1000, 'qədər' = Q − 1 yaz 7. Filtr panelinin altındakı 'Tətbiq et' düyməsini bas 8. Q qiymətli məhsulun nəticədə olmadığını yoxla | I20: Q + 1 və Q − 1 | J20: Hər iki halda Q qiymətli məhsul nəticədə yoxdur. | K20: Q+1 və Q−1 aralıqlarında Q qiymətli məhsul nəticədə yoxdur. | L20: Pass | M20: Avtomat | N20: A2 | O20: Xeyr | P20: Xeyr | R20: BR-04 | S20: Avtomatlaşdırılıb — PASS, 16.10.2026 | T20: Q icra zamanı ilk kartdan götürülür; [Q+1, Q+500] və [Q−500, Q−1] aralıqlarında Q qiymətli kart yoxdur
A21: TC_PLP_NEG_017 | B21: SC-003 | C21: Kateqoriya (PLP) | D21: Minimum maksimumdan böyük olduqda sistem istifadəçini məlumatlandırır | E21: P3 — Medium | F21: Neqativ · Funksional | G21: Ümumi ön şərt (P0): Chrome son versiya, inkognito pəncərə, 1920×1080, AZ dili, login olmadan | H21: 1. https://ispace.az/category/iphone ünvanını aç 2. 'Qiymət ₼' qrupunda 'dən' sahəsinə 3000 yaz 3. 'qədər' sahəsinə 1000 yaz 4. Filtr panelinin altındakı 'Tətbiq et' düyməsini bas 5. Göstərilən mesaja və nəticəyə bax | I21: min = 3000, max = 1000 (etibarsız sinif) | J21: Sistem ya xəta mesajı göstərir, ya da dəyərlərin yerini dəyişir. Mesajsız boş nəticə səhifəsi qəbuledilməzdir. Səhifə xəta vermir. | K21: min = 3000, max = 1000: səhifə xəta vermədi, 'Məhsul tapılmadı. Daha az filtrdən istifadə edin və ya Hamısını silin' boş vəziyyət mesajı göstərildi. Qeyd (UX təklifi): mesaj səbəbi (min > max) izah etmir — OBS-01. | L21: Pass | M21: Manual | N21: M5 — gözlənilən davranış tələbdə yoxdur, biznes qərarı lazımdır | O21: Xeyr | P21: Xeyr | R21: BR-04
A22: TC_PLP_NEG_018 | B22: SC-003 | C22: Kateqoriya (PLP) | D22: Qiymət sahəsi qeyri-rəqəm və mənfi dəyərləri qəbul etmir | E22: P3 — Medium | F22: Neqativ · Funksional | G22: Ümumi ön şərt (P0): Chrome son versiya, inkognito pəncərə, 1920×1080, AZ dili, login olmadan | H22: 1. https://ispace.az/category/iphone ünvanını aç 2. 'dən' sahəsinə 'abc' yazmağa çalış 3. Filtr panelinin altındakı 'Tətbiq et' düyməsini bas 4. Sahənin dəyərinə və nəticəyə bax 5. Sahəni təmizlə və '-100' yaz 6. Filtr panelinin altındakı 'Tətbiq et' düyməsini bas 7. Sahənin dəyərinə və nəticəyə bax 8. Sahəni təmizlə və '1 000,50' yaz 9. Filtr panelinin altındakı 'Tətbiq et' düyməsini bas 10. Sahənin dəyərinə və nəticəyə bax | I22: abc; -100; 1 000,50 | J22: Hərflər və mənfi işarə sahəyə yazılmır və ya filtr tətbiq olunmur və bildiriş göstərilir. Səhifə xəta vermir, nəticələr pozulmur. | K22: Mənfi işarə və '1 000,50' formatı sahəyə yazılmır; səhifə xəta vermir. | L22: Pass | M22: Manual | N22: M5 — bir dəfəlik input yoxlaması, regression dəyəri aşağı | O22: Xeyr | P22: Xeyr | R22: BR-04
A23: TC_PLP_POS_019 | B23: SC-004 | C23: Kateqoriya (PLP) | D23: 'Aşağı qiymət' sıralaması qiymətləri artan sırada göstərir | E23: P2 — High | F23: Pozitiv · Funksional | G23: Ümumi ön şərt (P0): Chrome son versiya, inkognito pəncərə, 1920×1080, AZ dili, login olmadan | H23: 1. https://ispace.az/category/iphone ünvanını aç 2. Məhsul siyahısının üstündəki sıralama siyahısını aç 3. 'Aşağı qiymət' seç 4. 1-ci səhifədəki qiymətləri yuxarıdan aşağı ardıcıl oxu və müqayisə et | I23: — | J23: Hər növbəti kartın qiyməti əvvəlkindən ≥-dir. | K23: 'Aşağı qiymət': qiymətlər artan sıradadır. | L23: Pass | M23: Avtomat | N23: A1, A2 | O23: Bəli | P23: Xeyr | R23: BR-03 | S23: Avtomatlaşdırılıb — PASS, 16.10.2026 | T23: Sıralama custom dropdown-dur (əsl select gizlidir); URL sort=cheap; Java: qiymətlər artan
A24: TC_PLP_POS_020 | B24: SC-004 | C24: Kateqoriya (PLP) | D24: 'Yüksək qiymət' sıralaması azalan sıradadır və ilk məhsul ən bahalısıdır | E24: P2 — High | F24: Pozitiv · Funksional | G24: Ümumi ön şərt (P0): Chrome son versiya, inkognito pəncərə, 1920×1080, AZ dili, login olmadan | H24: 1. https://ispace.az/category/iphone ünvanını aç 2. 'Qiymət ₼' qrupundakı 'Ən yüksək qiymət' dəyərini (Qmax) qeyd et 3. Sıralama siyahısından 'Yüksək qiymət' seç 4. İlk kartın qiymətini Qmax ilə müqayisə et 5. 1-ci səhifədəki qiymətlərin azalan sırada olduğunu yoxla | I24: Qmax — icra zamanı oxunur (04.10: 7 229 ₼) | J24: 1. Qiymətlər azalan sıradadır. 2. İlk kartın qiyməti = Qmax. | K24: 'Yüksək qiymət': qiymətlər azalan sıradadır, ilk kartın qiyməti filtrdəki 'Ən yüksək qiymət' ilə eynidir. | L24: Pass | M24: Avtomat | N24: A1, A2 | O24: Bəli | P24: Xeyr | R24: BR-03, BR-05 | S24: Avtomatlaşdırılıb — PASS, 16.10.2026 | T24: URL sort=expensive; Java: qiymətlər azalan; ilk kartın qiyməti = filtrdəki 'Ən yüksək qiymət'
A25: TC_PLP_POS_021 | B25: SC-004 | C25: Kateqoriya (PLP) | D25: Sıralama növbəti səhifədə də davam edir | E25: P3 — Medium | F25: Pozitiv · Funksional | G25: Ümumi ön şərt (P0): Chrome son versiya, inkognito pəncərə, 1920×1080, AZ dili, login olmadan | H25: 1. https://ispace.az/category/iphone ünvanını aç 2. Sıralama siyahısından 'Aşağı qiymət' seç 3. 1-ci səhifədəki son kartın qiymətini (Q1) qeyd et 4. Səhifənin altındakı səhifələmədən '2' bas 5. 2-ci səhifədəki ilk kartın qiymətini (Q2) qeyd et 6. URL-də sıralama parametrinin qaldığını yoxla | I25: — | J25: Q1 ≤ Q2 və 2-ci səhifədə də sıra artandır. URL-də sıralama parametri saxlanılır. | K25: 1-ci səhifənin son qiyməti ≤ 2-ci səhifənin ilk qiyməti; sıra 2-ci səhifədə də artandır. | L25: Pass | M25: Avtomat | N25: A2, A3 | O25: Xeyr | P25: Xeyr | R25: BR-03 | S25: Avtomatlaşdırılıb — PASS, 16.10.2026 | T25: 1-ci səhifənin son qiyməti ≤ 2-ci səhifənin ilk qiyməti; hər iki səhifə artan sıradadır
A26: TC_PLP_POS_022 | B26: SC-004 | C26: Kateqoriya (PLP) | D26: Səhifə ölçüsü və səhifə sayı ümumi məhsul sayına uyğundur | E26: P3 — Medium | F26: Pozitiv · Funksional | G26: Ümumi ön şərt (P0): Chrome son versiya, inkognito pəncərə, 1920×1080, AZ dili, login olmadan | H26: 1. https://ispace.az/category/iphone ünvanını aç 2. Səhifənin yuxarısındakı 'N Məhsul' mətnindən nəticə sayını qeyd et 3. 1-ci səhifədəki kartları say 4. Səhifələmədəki son səhifə nömrəsini qeyd et 5. Son səhifəni aç və kartları say | I26: 04.10: N = 213, səhifədə 21, 11 səhifə, sonuncuda 3 | J26: 1. Tam səhifələrdə 21 kart var. 2. Səhifə sayı = ⌈N / 21⌉. 3. Son səhifədə N − 21 × (səhifə sayı − 1) kart var. | K26: Tam səhifələrdə 21 kart, səhifə sayı ⌈N/21⌉, son səhifədəki kart sayı düsturla uyğundur (BR-14 təsdiqləndi). | L26: Pass | M26: Avtomat | N26: A2 | O26: Xeyr | P26: Xeyr | R26: BR-14
A27: TC_PLP_POS_023 | B27: SC-004 | C27: Kateqoriya (PLP) | D27: Səhifələr arasında məhsul təkrarlanmır və itmir | E27: P3 — Medium | F27: Pozitiv · Funksional | G27: Ümumi ön şərt (P0): Chrome son versiya, inkognito pəncərə, 1920×1080, AZ dili, login olmadan | H27: 1. https://ispace.az/category/iphone ünvanını aç 2. Hər səhifədə bütün kartların linkini (URL) siyahıya yaz 3. Səhifələmə ilə növbəti səhifəyə keç və təkrarla — son səhifəyə qədər 4. Toplanan URL-lərin sayını N ilə müqayisə et 5. Siyahıda təkrarlanan URL olub-olmadığını yoxla | I27: — | J27: Toplanmış URL-lərin sayı = N; təkrarlanan URL yoxdur. | K27: Bütün səhifələr ardıcıl açıldı; toplanan məhsul URL-lərinin sayı ümumi saya bərabərdir, təkrarlanan və ya itən məhsul yoxdur (10.10 təkrar icra). | L27: Pass | M27: Manual | N27: M3 — default 'Məşhur' sırası və eyni qiymətli məhsullar sorğular arasında yer dəyişə bilər → avtomat test flaky olar | O27: Xeyr | P27: Xeyr | R27: BR-03, BR-05, BR-14
A28: TC_FLT_POS_001 | B28: SC-005 | C28: Kateqoriya (PLP) | D28: 'iPhone 18 Pro & Pro Max' çipi seçildikdə nəticə sayı həmin seriyaların sayğaclarının cəminə bərabərdir | E28: P3 — Medium | F28: Pozitiv · Funksional | G28: Ümumi ön şərt (P0): Chrome son versiya, inkognito pəncərə, 1920×1080, AZ dili, login olmadan; filtr seçilməyib | H28: 1. https://ispace.az/category/iphone ünvanını aç 2. Filtr panelinin 'Seriya' qrupunda 'iPhone 18 Pro (N1)' və 'iPhone 18 Pro Max (N2)' sayğaclarını qeyd et 3. Səhifənin yuxarısındakı 'iPhone 18 Pro & iPhone 18 Pro Max' çipinə klik et 4. Açılan səhifənin URL-ini və başlığını qeyd et 5. Səhifənin yuxarısındakı 'N Məhsul' mətnindən nəticə sayını qeyd et 6. Nəticə sayını N1 + N2 ilə müqayisə et | I28: 10.10: N1 = 16, N2 = 16 → gözlənilən 32 | J28: /category/iphone-series-18-pro açılır; məhsul sayı = N1 + N2 (32); bütün kartlar iPhone 18 Pro və ya 18 Pro Max-dır. | K28: Gözlənilən nəticəyə uyğundur. | L28: Pass | M28: Avtomat | N28: A2 — iki səhifə arasında uyğunluq qaydası | O28: Xeyr | P28: Xeyr | R28: BR-12
A29: TC_FLT_POS_002 | B29: SC-005 | C29: Kateqoriya (PLP) | D29: Seriya filtri yalnız dəqiq seriyanı qaytarır (alt-seriyaları qarışdırmır) | E29: P2 — High | F29: Pozitiv · Funksional | G29: Ümumi ön şərt (P0): Chrome son versiya, inkognito pəncərə, 1920×1080, AZ dili, login olmadan; filtr seçilməyib | H29: 1. https://ispace.az/category/iphone ünvanını aç 2. 'Seriya' qrupunda yalnız 'iPhone 16 (N)' seç 3. Filtr panelinin altındakı 'Tətbiq et' düyməsini bas 4. Səhifənin yuxarısındakı 'N Məhsul' mətnindən nəticə sayını qeyd et 5. Bütün kartların adının 'iPhone 16,' ilə başladığını yoxla (16 Pro / Plus / Pro Max / 16e olmamalıdır) 6. Seçimi götür, yalnız 'iPhone 15' seç 7. Filtr panelinin altındakı 'Tətbiq et' düyməsini bas 8. Adları eyni qayda ilə yoxla | I29: 10.10: iPhone 16 (17), iPhone 15 (15) | J29: Nəticə sayı = N. Bütün adlar 'iPhone 16,' ilə başlayır; 'iPhone 16 Pro', 'iPhone 16 Plus', 'iPhone 16 Pro Max', 'iPhone 16e' nəticədə YOXDUR. Mətnə əsaslanan 'contains' axtarışı səhvini tutur. | K29: Gözlənilən nəticəyə uyğundur. | L29: Pass | M29: Avtomat | N29: A1, A2 — tipik substring bug-ı, regression üçün dəyərli | O29: Bəli | P29: Xeyr | R29: BR-02 | S29: Avtomatlaşdırılıb — PASS, 16.10.2026 | T29: Desktop-da filtr dərhal tətbiq olunur; bütün adlarda 'iPhone 16,' (vergüllə) yoxlanır
A30: TC_FLT_POS_003 | B30: SC-005 | C30: Kateqoriya (PLP) | D30: Bütün Seriya sayğaclarının cəmi ümumi məhsul sayına bərabərdir ('Daha çox göstər' açıq) | E30: P3 — Medium | F30: Pozitiv · Funksional | G30: Ümumi ön şərt (P0): Chrome son versiya, inkognito pəncərə, 1920×1080, AZ dili, login olmadan; filtr seçilməyib | H30: 1. https://ispace.az/category/iphone ünvanını aç 2. 'Seriya' qrupunda '+ Daha çox göstər' bas 3. Bütün seriyaların sayğaclarını topla 4. Cəmi ümumi 'N Məhsul' ilə müqayisə et | I30: 10.10: görünən 10 seriyanın cəmi 150; gizli seriyalarla 213 olmalıdır | J30: Cəm = 213. Az olarsa — seriyası təyin edilməmiş məhsullar var (Seriya filtri ilə tapılmır); çox olarsa — bir məhsul iki seriyaya bağlanıb. | K30: Gözlənilən nəticəyə uyğundur. | L30: Pass | M30: Avtomat | N30: A2 | O30: Xeyr | P30: Xeyr | R30: BR-12
A31: TC_FLT_POS_004 | B31: SC-006 | C31: Kateqoriya (PLP) | D31: Ekran diaqonalı filtri: say və PDP göstəricisi uyğundur | E31: P3 — Medium | F31: Pozitiv · Funksional | G31: Ümumi ön şərt (P0): Chrome son versiya, inkognito pəncərə, 1920×1080, AZ dili, login olmadan; filtr seçilməyib | H31: 1. https://ispace.az/category/iphone ünvanını aç 2. 'Ekran diaqonalı' qrupunda '6.90" (N)' seç 3. Filtr panelinin altındakı 'Tətbiq et' düyməsini bas 4. Səhifənin yuxarısındakı 'N Məhsul' mətnindən nəticə sayını qeyd et 5. Təsadüfi 3 nəticənin məhsul səhifəsini aç və 'Ekran diaqonalı' göstəricisini oxu 6. Filtri '7.60"' ilə dəyiş 7. Filtr panelinin altındakı 'Tətbiq et' düyməsini bas 8. Nəticədəki modellərin adlarını qeyd et | I31: 10.10: 6.90" (40), 7.60" (8) | J31: Say = sayğac; seçilmiş PDP-lərdə 'Ekran diaqonalı 6.90"'. 7.60" nəticələri yalnız həmin ölçülü modeldir (məs. iPhone Duo) — məntiqsiz model (məs. iPhone 16e) yoxdur. | K31: Gözlənilən nəticəyə uyğundur. | L31: Pass | M31: Avtomat | N31: A2 — filtr datası ilə PDP datasının uyğunluğu | O31: Xeyr | P31: Xeyr | R31: BR-12
A32: TC_FLT_POS_005 | B32: SC-006 | C32: Kateqoriya (PLP) | D32: '48 MP' əsas kamera filtri seçildikdə yalnız tək arxa kameralı modellər göstərilir (12 məhsul) | E32: P3 — Medium | F32: Pozitiv · Funksional | G32: Ümumi ön şərt (P0): Chrome son versiya, inkognito pəncərə, 1920×1080, AZ dili, login olmadan; filtr seçilməyib | H32: 1. https://ispace.az/category/iphone ünvanını aç 2. 'Əsas kamera' qrupunda '48 Mpixel (N)' seç 3. Filtr panelinin altındakı 'Tətbiq et' düyməsini bas 4. Səhifənin yuxarısındakı 'N Məhsul' mətnindən nəticə sayını qeyd et 5. Nəticədəki model adlarını qeyd et 6. 2 nəticənin məhsul səhifəsində 'Əsas kamera' göstəricisini oxu | I32: 10.10: 48 Mpixel (12) | J32: Say = 12; nəticələr yalnız tək arxa kameralı modellərdir (məs. iPhone 16e, 17e, Air); PDP-də 'Əsas kamera 48 Mpixel'. Pro modeli bu qrupa düşmür. | K32: Gözlənilən nəticəyə uyğundur. | L32: Pass | M32: Avtomat | N32: A2 | O32: Xeyr | P32: Xeyr | R32: BR-12
A33: TC_FLT_EDGE_006 | B33: SC-006 | C33: Kateqoriya (PLP) | D33: 'Video izləmə müddəti' filtrinin bütün dəyərləri azərbaycanca və eyni vahidlə ('saat') yazılır | E33: P4 — Low | F33: Edge Case · Funksional | G33: Ümumi ön şərt (P0): Chrome son versiya, inkognito pəncərə, 1920×1080, AZ dili, login olmadan; filtr seçilməyib | H33: 1. https://ispace.az/category/iphone ünvanını aç 2. 'Video izləmə müddəti' qrupunda '+ Daha çox göstər' bas 3. Qrupdakı bütün dəyərləri siyahıya yaz 4. Hər dəyərin vahidini ('saat' və ya başqa) qeyd et | I33: 10.10: '36 Hours (16)', '45 Hours (16)' — digərləri 'saat' | J33: Bütün dəyərlər 'saat' vahidi ilə, azərbaycanca yazılır; '36 Hours', '45 Hours' kimi ingiliscə dəyər yoxdur. | K33: AZ səhifədə '36 Hours' və '45 Hours' dəyərləri ingiliscədir, digər dəyərlər 'saat' ilə yazılıb (10.10 icrası). | L33: Fail | M33: Manual | N33: M1 — data keyfiyyəti və tərcümə | O33: Xeyr | P33: Xeyr | Q33: BUG-011 | R33: BR-18
A34: TC_FLT_EDGE_007 | B34: SC-006 | C34: Kateqoriya (PLP) | D34: '36 Hours' filtri ilə tapılan modellərin məhsul səhifəsindəki video izləmə müddəti 36 saatdır | E34: P4 — Low | F34: Edge Case · Funksional | G34: Ümumi ön şərt (P0): Chrome son versiya, inkognito pəncərə, 1920×1080, AZ dili, login olmadan; filtr seçilməyib | H34: 1. https://ispace.az/category/iphone ünvanını aç 2. 'Video izləmə müddəti' qrupunda '+ Daha çox göstər' bas 3. '36 Hours' seç 4. Filtr panelinin altındakı 'Tətbiq et' düyməsini bas 5. Birinci nəticənin məhsul səhifəsini aç 6. 'Texniki göstəricilər'də video izləmə müddətini oxu 7. Digər 2 nəticə üçün 5–6-cı addımları təkrarla | I34: 'Video izləmə müddəti' = '36 Hours' (10.10: 16 nəticə) | J34: Nəticədəki hər modelin məhsul səhifəsində video izləmə müddəti 36 saatdır. | K34: '36 Hours' seçildikdə nəticədə olan 'iPhone 18 Pro, 512 GB, Burgundy' məhsul səhifəsində video izləmə müddəti 34 saata qədər göstərilir — filtr dəyəri ilə uyğun deyil (10.10 icrası). | L34: Fail | M34: Manual | N34: M1 — PDP göstəricisi ilə müqayisə | O34: Xeyr | P34: Xeyr | Q34: BUG-021 | R34: BR-18
A35: TC_FLT_POS_008 | B35: SC-006 | C35: Kateqoriya (PLP) | D35: SIM kart növü filtri bir-birini istisna edir | E35: P3 — Medium | F35: Pozitiv · Funksional | G35: Ümumi ön şərt (P0): Chrome son versiya, inkognito pəncərə, 1920×1080, AZ dili, login olmadan; filtr seçilməyib | H35: 1. https://ispace.az/category/iphone ünvanını aç 2. 'SIM kart növü' qrupunda 'eSIM (N1)' seç 3. Filtr panelinin altındakı 'Tətbiq et' düyməsini bas 4. Səhifənin yuxarısındakı 'N Məhsul' mətnindən nəticə sayını qeyd et 5. 2 nəticənin məhsul səhifəsində 'SIM kart növü'nü oxu 6. Seçimi 'Nano-SIM + eSIM (N2)' ilə dəyiş 7. Filtr panelinin altındakı 'Tətbiq et' düyməsini bas 8. Nəticədə eSIM-only modellərin olmadığını yoxla 9. N1 + N2-ni ümumi say ilə müqayisə et | I35: 10.10: eSIM (26), Nano-SIM + eSIM (187) | J35: eSIM nəticələri = 26 və PDP-də 'eSIM'; Nano-SIM + eSIM nəticələrində eSIM-only modellər yoxdur; 26 + 187 = 213. | K35: eSIM nəticələri sayğacla uyğundur və məhsul səhifələrində 'eSIM' yazılıb; 'Nano-SIM + eSIM' nəticələrində eSIM-only modellər yoxdur; 26 + 187 = 213. | L35: Pass | M35: Avtomat | N35: A2 | O35: Xeyr | P35: Xeyr | R35: BR-12
A36: TC_FLT_EDGE_009 | B36: SC-007 | C36: Kateqoriya (PLP) | D36: Hər məhsul ən azı bir Rəng dəyərinə bağlıdır (rəng sayğacları cəmi = 213) | E36: P3 — Medium | F36: Edge Case · Funksional | G36: Ümumi ön şərt (P0): Chrome son versiya, inkognito pəncərə, 1920×1080, AZ dili, login olmadan; filtr seçilməyib | H36: 1. https://ispace.az/category/iphone ünvanını aç 2. 'Rəng' qrupunda '+ Daha çox göstər' bas 3. Bütün rəng sayğaclarını topla 4. Cəmi ümumi 'N Məhsul' ilə müqayisə et | I36: 10.10: görünən 10 rəngin cəmi 204; gizlilərlə 213 olmalıdır | J36: Cəm = 213. Az olarsa — rəngi təyin edilməmiş məhsullar var (məs. Lavender, Sage, Cosmic Orange, Glacier, Burgundy) və onlar heç bir rəng filtri ilə tapılmır. | K36: 'Daha çox göstər' açıq halda rəng sayğaclarının cəmi = 213; hər məhsul bir rəngə bağlıdır. | L36: Pass | M36: Avtomat | N36: A2 | O36: Xeyr | P36: Xeyr | R36: BR-12
A37: TC_FLT_EDGE_010 | B37: SC-007 | C37: Kateqoriya (PLP) | D37: Hər modelin Apple rəng adı vizual rənginə uyğun Rəng filtri dəyərində tapılır | E37: P3 — Medium | F37: Edge Case · Funksional | G37: Ümumi ön şərt (P0): Chrome son versiya, inkognito pəncərə, 1920×1080, AZ dili, login olmadan; filtr seçilməyib | H37: 1. https://ispace.az/category/iphone ünvanını aç 2. 'Rəng' qrupunda test datasındakı birinci modelə uyğun rəngi seç 3. Filtr panelinin altındakı 'Tətbiq et' düyməsini bas 4. Modelin nəticədə olub-olmadığını qeyd et 5. Test datasındakı digər modellər üçün 2–4-cü addımları təkrarla | I37: Model → gözlənilən rəng filtri: iPhone 17 Lavender → Bənövşəyi/Cəhrayı; iPhone 17 Sage → Yaşıl; iPhone 17 Pro Cosmic Orange → Narıncı; iPhone 17 Pro Max Deep Blue → Mavi; iPhone 18 Pro Glacier → Ağ/Gümüş; iPhone 18 Pro Burgundy → Qırmızı | J37: Hər model vizual rənginə uyğun bir filtrdə tapılır. Heç bir filtrdə tapılmayan və ya açıq-aydın səhv rəngdə olan (məs. Burgundy → Mavi) model — data bug-ı. | K37: Gözlənilən nəticəyə uyğundur. | L37: Pass | M37: Manual | N37: M1 — rəng uyğunluğu insan qiymətləndirməsidir | O37: Xeyr | P37: Xeyr | R37: BR-18
A38: TC_FLT_EDGE_011 | B38: SC-007 | C38: Kateqoriya (PLP) | D38: 'Əlavə xüsusiyyətlər' filtri bütün uyğun məhsulları qaytarır (data tamlığı) | E38: P2 — High | F38: Edge Case · Funksional | G38: Ümumi ön şərt (P0): Chrome son versiya, inkognito pəncərə, 1920×1080, AZ dili, login olmadan; filtr seçilməyib | H38: 1. https://ispace.az/category/iphone ünvanını aç 2. 'Əlavə xüsusiyyətlər' qrupunda 'Dynamic Island (N)' seç 3. Filtr panelinin altındakı 'Tətbiq et' düyməsini bas 4. Səhifənin yuxarısındakı 'N Məhsul' mətnindən nəticə sayını qeyd et 5. Nəticədəki model adlarını qeyd et 6. Filtrsiz siyahıda Dynamic Island olan modellərin (iPhone 15 / 16 / 17 / 18) sayını N ilə müqayisə et | I38: 10.10: bütün xüsusiyyətlər yalnız (8). Dynamic Island iPhone 15-dən bəri bütün əsas modellərdədir — kateqoriyada 100+ belə məhsul var | J38: Filtr xüsusiyyəti olan bütün məhsulları qaytarır və ya xüsusiyyət datası tam deyilsə filtr göstərilmir. 8 nəticə — istifadəçi uyğun modellərin 90%-dən çoxunu görmür (data bug-ı). | K38: Gözlənilən nəticəyə uyğundur. | L38: Pass | M38: Manual | N38: M1 — gözlənilən say Apple spesifikasiyasına əsaslanır, insan yoxlaması lazımdır | O38: Xeyr | P38: Xeyr | R38: BR-18
A39: TC_FLT_UI_012 | B39: SC-007 | C39: Kateqoriya (PLP) | D39: 'Əlavə xüsusiyyətlər' dəyərləri azərbaycancadır | E39: P4 — Low | F39: UI | G39: Ümumi ön şərt (P0): Chrome son versiya, inkognito pəncərə, 1920×1080, AZ dili, login olmadan; filtr seçilməyib | H39: 1. https://ispace.az/category/iphone ünvanını aç 2. 'Əlavə xüsusiyyətlər' qrupunda '+ Daha çox göstər' bas 3. Qrupdakı bütün dəyərləri oxu və dilini qeyd et | I39: 10.10: 'ProMotion technology with adaptive refresh rates up to 120Hz', '1600 nits peak brightness (HDR)', '3000 nits peak brightness (outdoor)', 'Always On display' | J39: Bütün dəyərlər azərbaycancadır (brend terminləri — Dynamic Island, True Tone — istisna ola bilər). | K39: AZ səhifədə 'Əlavə xüsusiyyətlər' dəyərlərinin bir qismi azərbaycanca, bir qismi ingiliscədir (məs. 'ProMotion technology with adaptive refresh rates up to 120Hz', '… nits peak brightness'). | L39: Fail | M39: Manual | N39: M1 | O39: Xeyr | P39: Xeyr | Q39: BUG-020 | R39: BR-18
A40: TC_FLT_POS_013 | B40: SC-008 | C40: Kateqoriya (PLP) | D40: Filtr seçildikdən sonra digər qrupların sayğacları nəticəyə görə yenilənir | E40: P2 — High | F40: Pozitiv · Funksional | G40: Ümumi ön şərt (P0): Chrome son versiya, inkognito pəncərə, 1920×1080, AZ dili, login olmadan; filtr seçilməyib | H40: 1. https://ispace.az/category/iphone ünvanını aç 2. 'Yaddaş' qrupunda '2 TB (N)' seç 3. Filtr panelinin altındakı 'Tətbiq et' düyməsini bas 4. 'Rəng', 'Seriya' və 'Stokda var' qruplarının sayğaclarını oxu 5. Hər qrupun sayğac cəmini N ilə müqayisə et | I40: 10.10: 2 TB (13) | J40: Bütün qrupların sayğacları yalnız 2 TB nəticələrinə aiddir; hər bir-birini istisna edən qrupda cəm = 13; 0 nəticəli dəyərlər gizlənir və ya deaktivdir. Sayğaclar dəyişmirsə — istifadəçi '0 nəticə' verən kombinasiyalar seçir. | K40: Gözlənilən nəticəyə uyğundur. | L40: Pass | M40: Avtomat | N40: A2 | O40: Xeyr | P40: Xeyr | R40: BR-12
A41: TC_FLT_POS_014 | B41: SC-008 | C41: Kateqoriya (PLP) | D41: 'Tətbiq et' basılmadan seçim nəticəni dəyişmir və itmir | E41: P3 — Medium | F41: Pozitiv · Funksional | G41: Ümumi ön şərt (P0): Chrome son versiya, inkognito pəncərə, 1920×1080, AZ dili, login olmadan; filtr seçilməyib | H41: 1. https://ispace.az/category/iphone ünvanını aç 2. Səhifənin yuxarısındakı 'N Məhsul' mətnindən nəticə sayını qeyd et 3. 'Yaddaş' qrupunda '512 GB' seç — 'Tətbiq et' BASMA 4. Səhifənin yuxarısındakı 'N Məhsul' mətnindən nəticə sayını qeyd et — dəyişməməlidir 5. Sıralama siyahısından 'Aşağı qiymət' seç 6. Filtr panelindəki '512 GB' işarəsinə və nəticəyə bax | I41: — | J41: 'Tətbiq et'-ə qədər nəticə dəyişmir. Sıralama dəyişəndə tətbiq olunmamış seçim ya ləğv olunur, ya da açıq şəkildə tətbiq edilir — panel və nəticə arasında ziddiyyət (checkbox seçili, nəticə filtrsiz) yoxdur. | K41: Gözlənilən nəticəyə uyğundur. | L41: Pass | M41: Avtomat | N41: A2 | O41: Xeyr | P41: Xeyr | R41: BR-02, BR-12
A42: TC_FLT_POS_015 | B42: SC-008 | C42: Kateqoriya (PLP) | D42: '+ Daha çox göstər' gizli dəyəri seçdikdən sonra aktiv filtr görünür qalır | E42: P3 — Medium | F42: Pozitiv · Funksional | G42: Ümumi ön şərt (P0): Chrome son versiya, inkognito pəncərə, 1920×1080, AZ dili, login olmadan; filtr seçilməyib | H42: 1. https://ispace.az/category/iphone ünvanını aç 2. 'Rəng' qrupunda '+ Daha çox göstər' bas 3. Yalnız gizli siyahıda olan bir rəngi seç 4. Filtr panelinin altındakı 'Tətbiq et' düyməsini bas 5. Səhifə yeniləndikdən sonra 'Rəng' qrupunda seçilmiş rəngin göründüyünü yoxla | I42: — | J42: Qrup açılır/bağlanır; seçilmiş gizli dəyər tətbiqdən sonra görünür (qrup açıq qalır və ya seçilmiş dəyər yuxarıda göstərilir). İstifadəçi aktiv filtri axtarmaq məcburiyyətində qalmır. | K42: Gözlənilən nəticəyə uyğundur. | L42: Pass | M42: Manual | N42: M1 | O42: Xeyr | P42: Xeyr | R42: BR-02, BR-12
...

Sheet RTM
A1: Requirement Traceability Matrix (RTM) — iSpace.az
E3: Eyni məhsulun qiyməti listing, PDP və səbətdə eynidir | F3: Filtr yanındakı sayğac (N) filtr tətbiq edildikdən sonrakı n | G3: 'Aşağı qiymət' artan, 'Yüksək qiymət' azalan sıra verir — bü | H3: Qiymət aralığı filtri yalnız [min; max] daxilində (sərhədlər | I3: Filtrdə göstərilən 'Ən yüksək qiymət' kateqoriyadakı ən baha | J3: Variant (yaddaş/rəng) dəyişəndə məhsul kodu, qiymət və URL müvafiq v | K3: Səbət cəmi = Σ (qiymət × miqdar) + seçilmiş əlavə proqramlar | L3: 0% taksitdə aylıq məbləğ = qiymət / ay sayı, ən yaxın tam ma | M3: 24 aylıq taksitdə aylıq məbləğ qiymət/24-dən ~12–13% yüksəkd | N3: Dil keçidi istifadəçini eyni səhifənin digər dil versiyasına | O3: Məhsul kartında vəziyyətə görə 4 düymədən biri göstərilir: ' | P3: Bir-birini istisna edən filtr qrupunda (stok, yaddaş, SIM, e | Q3: Bakı: 16:00-dək rəsmiləşdirilən sifariş eyni gün; haqq 4–50 | R3: Səhifədə 21 məhsul göstərilir; səhifə sayı = ⌈N/21⌉ | S3: Miqdar mövcud stok sayından artıq seçilə bilmir; həddə çatan | T3: Axtarış sorğusu ən az 3 simvol olmalıdır; daha qısa sorğuda | U3: 0% hissə-hissə ödəniş: 2–24 ay (/credit) və ya 3–24 ay (/pay | V3: Filtrlər 'Tətbiq et' ilə tətbiq olunur. Hər filtr dəyəri məh | W3: −15% VİSA' endirimi yalnız 'Apple Pay vasitəsilə Visa ilə ö | X3: Checkout formasında telefon və e-poçt formatı yoxlanılır; sə
A4: TC ID | B4: Başlıq | C4: Ssenari | D4: Status | E4: BR-01 | F4: BR-02 | G4: BR-03 | H4: BR-04 | I4: BR-05 | J4: BR-06 | K4: BR-07 | L4: BR-08 | M4: BR-09 | N4: BR-10 | O4: BR-11 | P4: BR-12 | Q4: BR-13 | R4: BR-14 | S4: BR-15 | T4: BR-16 | U4: BR-17 | V4: BR-18 | W4: BR-19 | X4: BR-20
A5: ='Web Test Cases'!A5 -> TC_PLP_POS_001 | B5: ='Web Test Cases'!D5 -> iPhone kateqoriyası açıldıqda başlıq, breadcrumb, məhsul sayı və məhsul kartları göstərilir | C5: ='Web Test Cases'!B5 -> SC-001 | D5: ='Web Test Cases'!L5 -> Pass | E5: ✓ | O5: ✓
A6: ='Web Test Cases'!A6 -> TC_PLP_POS_002 | B6: ='Web Test Cases'!D6 -> Hər məhsul kartında ad, qiymət, aylıq ödəniş və düymə göstərilir | C6: ='Web Test Cases'!B6 -> SC-001 | D6: ='Web Test Cases'!L6 -> Pass | E6: ✓ | O6: ✓
A7: ='Web Test Cases'!A7 -> TC_PLP_POS_003 | B7: ='Web Test Cases'!D7 -> Kartdakı qiymət məhsul səhifəsindəki qiymətlə eynidir | C7: ='Web Test Cases'!B7 -> SC-001 | D7: ='Web Test Cases'!L7 -> Pass | E7: ✓
A8: ='Web Test Cases'!A8 -> TC_PLP_POS_004 | B8: ='Web Test Cases'!D8 -> Stokda olan məhsulun kartında 'Səbətə', olmayanda 'Ön sifariş' / 'Mənə xəbər ver' düyməsi göstərilir | C8: ='Web Test Cases'!B8 -> SC-001 | D8: ='Web Test Cases'!L8 -> Pass | O8: ✓
A9: ='Web Test Cases'!A9 -> TC_PLP_POS_005 | B9: ='Web Test Cases'!D9 -> 'Mövcuddur' filtri: nəticə sayı sayğaca bərabərdir | C9: ='Web Test Cases'!B9 -> SC-002 | D9: ='Web Test Cases'!L9 -> Pass | F9: ✓
A10: ='Web Test Cases'!A10 -> TC_PLP_POS_006 | B10: ='Web Test Cases'!D10 -> Bir filtr qrupunda sayğacların cəmi ümumi məhsul sayına bərabərdir | C10: ='Web Test Cases'!B10 -> SC-002 | D10: ='Web Test Cases'!L10 -> Pass | P10: ✓
A11: ='Web Test Cases'!A11 -> TC_PLP_POS_007 | B11: ='Web Test Cases'!D11 -> Yaddaş filtri yalnız seçilmiş yaddaşlı məhsulları göstərir | C11: ='Web Test Cases'!B11 -> SC-002 | D11: ='Web Test Cases'!L11 -> Pass | F11: ✓
A12: ='Web Test Cases'!A12 -> TC_PLP_POS_008 | B12: ='Web Test Cases'!D12 -> Rəng filtri yalnız seçilmiş rəngli məhsulları göstərir | C12: ='Web Test Cases'!B12 -> SC-002 | D12: ='Web Test Cases'!L12 -> Pass | F12: ✓
A13: ='Web Test Cases'!A13 -> TC_PLP_POS_009 | B13: ='Web Test Cases'!D13 -> '256 GB' və 'Mövcuddur' birlikdə seçildikdə yalnız hər iki şərtə uyğun məhsullar göstərilir (VƏ məntiqi) | C13: ='Web Test Cases'!B13 -> SC-002 | D13: ='Web Test Cases'!L13 -> Pass | F13: ✓ | P13: ✓
A14: ='Web Test Cases'!A14 -> TC_PLP_POS_010 | B14: ='Web Test Cases'!D14 -> '256 GB' və '512 GB' birlikdə seçildikdə nəticə sayı iki sayğacın cəminə bərabərdir (VƏ YA məntiqi) | C14: ='Web Test Cases'!B14 -> SC-002 | D14: ='Web Test Cases'!L14 -> Pass | P14: ✓
A15: ='Web Test Cases'!A15 -> TC_PLP_POS_011 | B15: ='Web Test Cases'!D15 -> Filtrlər təmizlənəndə ilkin siyahı bərpa olunur | C15: ='Web Test Cases'!B15 -> SC-002 | D15: ='Web Test Cases'!L15 -> Pass | F15: ✓ | P15: ✓
A16: ='Web Test Cases'!A16 -> TC_PLP_POS_012 | B16: ='Web Test Cases'!D16 -> Filtrli səhifə yeniləndikdə və link yeni tabda açıldıqda filtr qorunur | C16: ='Web Test Cases'!B16 -> SC-002 | D16: ='Web Test Cases'!L16 -> Pass | F16: ✓ | P16: ✓
A17: ='Web Test Cases'!A17 -> TC_PLP_NEG_013 | B17: ='Web Test Cases'!D17 -> Nəticəsiz filtr kombinasiyasında boş vəziyyət mesajı göstərilir | C17: ='Web Test Cases'!B17 -> SC-002 | D17: ='Web Test Cases'!L17 -> Pass | F17: ✓ | P17: ✓
A18: ='Web Test Cases'!A18 -> TC_PLP_POS_014 | B18: ='Web Test Cases'!D18 -> Qiymət aralığı daxilində olan məhsullar göstərilir | C18: ='Web Test Cases'!B18 -> SC-003 | D18: ='Web Test Cases'!L18 -> Pass | H18: ✓
A19: ='Web Test Cases'!A19 -> TC_PLP_BVA_015 | B19: ='Web Test Cases'!D19 -> Qiymət filtrinin sərhədləri daxildir (min = max = məhsulun qiyməti) | C19: ='Web Test Cases'!B19 -> SC-003 | D19: ='Web Test Cases'!L19 -> Pass | H19: ✓
A20: ='Web Test Cases'!A20 -> TC_PLP_BVA_016 | B20: ='Web Test Cases'!D20 -> Sərhəddən bir vahid kənar dəyər məhsulu xaric edir | C20: ='Web Test Cases'!B20 -> SC-003 | D20: ='Web Test Cases'!L20 -> Pass | H20: ✓
A21: ='Web Test Cases'!A21 -> TC_PLP_NEG_017 | B21: ='Web Test Cases'!D21 -> Minimum maksimumdan böyük olduqda sistem istifadəçini məlumatlandırır | C21: ='Web Test Cases'!B21 -> SC-003 | D21: ='Web Test Cases'!L21 -> Pass | H21: ✓
A22: ='Web Test Cases'!A22 -> TC_PLP_NEG_018 | B22: ='Web Test Cases'!D22 -> Qiymət sahəsi qeyri-rəqəm və mənfi dəyərləri qəbul etmir | C22: ='Web Test Cases'!B22 -> SC-003 | D22: ='Web Test Cases'!L22 -> Pass | H22: ✓
A23: ='Web Test Cases'!A23 -> TC_PLP_POS_019 | B23: ='Web Test Cases'!D23 -> 'Aşağı qiymət' sıralaması qiymətləri artan sırada göstərir | C23: ='Web Test Cases'!B23 -> SC-004 | D23: ='Web Test Cases'!L23 -> Pass | G23: ✓
A24: ='Web Test Cases'!A24 -> TC_PLP_POS_020 | B24: ='Web Test Cases'!D24 -> 'Yüksək qiymət' sıralaması azalan sıradadır və ilk məhsul ən bahalısıdır | C24: ='Web Test Cases'!B24 -> SC-004 | D24: ='Web Test Cases'!L24 -> Pass | G24: ✓ | I24: ✓
A25: ='Web Test Cases'!A25 -> TC_PLP_POS_021 | B25: ='Web Test Cases'!D25 -> Sıralama növbəti səhifədə də davam edir | C25: ='Web Test Cases'!B25 -> SC-004 | D25: ='Web Test Cases'!L25 -> Pass | G25: ✓
A26: ='Web Test Cases'!A26 -> TC_PLP_POS_022 | B26: ='Web Test Cases'!D26 -> Səhifə ölçüsü və səhifə sayı ümumi məhsul sayına uyğundur | C26: ='Web Test Cases'!B26 -> SC-004 | D26: ='Web Test Cases'!L26 -> Pass | R26: ✓
A27: ='Web Test Cases'!A27 -> TC_PLP_POS_023 | B27: ='Web Test Cases'!D27 -> Səhifələr arasında məhsul təkrarlanmır və itmir | C27: ='Web Test Cases'!B27 -> SC-004 | D27: ='Web Test Cases'!L27 -> Pass | G27: ✓ | I27: ✓ | R27: ✓
A28: ='Web Test Cases'!A28 -> TC_FLT_POS_001 | B28: ='Web Test Cases'!D28 -> 'iPhone 18 Pro & Pro Max' çipi seçildikdə nəticə sayı həmin seriyaların sayğaclarının cəminə bərabərdir | C28: ='Web Test Cases'!B28 -> SC-005 | D28: ='Web Test Cases'!L28 -> Pass | P28: ✓
A29: ='Web Test Cases'!A29 -> TC_FLT_POS_002 | B29: ='Web Test Cases'!D29 -> Seriya filtri yalnız dəqiq seriyanı qaytarır (alt-seriyaları qarışdırmır) | C29: ='Web Test Cases'!B29 -> SC-005 | D29: ='Web Test Cases'!L29 -> Pass | F29: ✓
